Workbook

Sheet Dashboard
A1: PIQUINZADA 2027 | DASHBOARD EXECUTIVO PMO
A2: Atualizado automaticamente a partir de ENTRADAS PMO, VENDAS, PATROCINIOS e CUSTOS.
A4: CENÁRIO CONSERVADOR | D4: CENÁRIO BASE | G4: CENÁRIO AGRESSIVO
A5: Receita total | B5: =Cenarios!$J$10 -> 195458 | D5: Receita total | E5: =Cenarios!$J$11 -> 491026.5 | G5: Receita total | H5: =Cenarios!$J$12 -> 689420
A6: ↳ Receita de ingressos | B6: =Cenarios!$F$10 -> 113758 | D6: ↳ Receita de ingressos | E6: =Cenarios!$F$11 -> 278520.8 | G6: ↳ Receita de ingressos | H6: =Cenarios!$F$12 -> 321770
A7: ↳ Receita de patrocínio | B7: =Cenarios!$H$10 -> 47820 | D7: ↳ Receita de patrocínio | E7: =Cenarios!$H$11 -> 127000 | G7: ↳ Receita de patrocínio | H7: =Cenarios!$H$12 -> 257400
A8: ↳ Receita de consumo/ativações | B8: =Cenarios!$G$10 -> 33880 | D8: ↳ Receita de consumo/ativações | E8: =Cenarios!$G$11 -> 85505.7 | G8: ↳ Receita de consumo/ativações | H8: =Cenarios!$G$12 -> 110250
A9: Custo total | B9: =Cenarios!$K$10 -> 403049.8 | D9: Custo total | E9: =Cenarios!$K$11 -> 475795.43 | G9: Custo total | H9: =Cenarios!$K$12 -> 571042.67
A10: RESULTADO (lucro/prejuízo) | B10: =Cenarios!$L$10 -> -207591.8 | D10: RESULTADO (lucro/prejuízo) | E10: =Cenarios!$L$11 -> 15231.069 | G10: RESULTADO (lucro/prejuízo) | H10: =Cenarios!$L$12 -> 118377.33
A11: Margem líquida | B11: =Cenarios!$M$10 -> -1.0620788 | D11: Margem líquida | E11: =Cenarios!$M$11 -> 0.031018833 | G11: Margem líquida | H11: =Cenarios!$M$12 -> 0.17170568
A12: Quantidade de pagantes | B12: =Cenarios!$B$10 -> 1540 | D12: Quantidade de pagantes | E12: =Cenarios!$B$11 -> 2850 | G12: Quantidade de pagantes | H12: =Cenarios!$B$12 -> 3150
A13: Capacidade utilizada | B13: =Cenarios!$D$10 -> 0.75454545 | D13: Capacidade utilizada | E13: =Cenarios!$D$11 -> 1 | G13: Capacidade utilizada | H13: =Cenarios!$D$12 -> 0.95142857
A14: Ticket médio | B14: =Cenarios!$E$10 -> 80.292208 | D14: Ticket médio | E14: =Cenarios!$E$11 -> 106.22456 | G14: Ticket médio | H14: =Cenarios!$E$12 -> 111.03175
A15: Ponto de equilíbrio (pagantes) | B15: =Cenarios!$R$10 -> 3705.3733 | D15: Ponto de equilíbrio (pagantes) | E15: =Cenarios!$R$11 -> 2730.7544 | G15: Ponto de equilíbrio (pagantes) | H15: =Cenarios!$R$12 -> 2286.8719
A16: % capacidade necessário p/ break-even | B16: =Cenarios!$S$10 -> 1.6842606 | D16: % capacidade necessário p/ break-even | E16: =Cenarios!$S$11 -> 0.91025148 | G16: % capacidade necessário p/ break-even | H16: =Cenarios!$S$12 -> 0.65339198
A17: Receita por participante | B17: =Cenarios!$N$10 -> 126.92078 | D17: Receita por participante | E17: =Cenarios!$N$11 -> 172.29 | G17: Receita por participante | H17: =Cenarios!$N$12 -> 218.86349
A18: Custo por participante | B18: =Cenarios!$O$10 -> 261.72065 | D18: Custo por participante | E18: =Cenarios!$O$11 -> 166.94577 | G18: Custo por participante | H18: =Cenarios!$O$12 -> 181.28339
A19: Patrocínio necessário (mín. p/ cachê) | B19: =Cenarios!$U$10 -> 160000 | D19: Patrocínio necessário (mín. p/ cachê) | E19: =Cenarios!$U$11 -> 180000 | G19: Patrocínio necessário (mín. p/ cachê) | H19: =Cenarios!$U$12 -> 200000
A20: Patrocínio já considerado no cenário | B20: =Cenarios!$H$10 -> 47820 | D20: Patrocínio já considerado no cenário | E20: =Cenarios!$H$11 -> 127000 | G20: Patrocínio já considerado no cenário | H20: =Cenarios!$H$12 -> 257400
A21: Cobertura do cachê pelo patrocínio | B21: =Cenarios!$H$10/'ENTRADAS PMO'!$C$39 -> 0.298875 | D21: Cobertura do cachê pelo patrocínio | E21: =Cenarios!$H$11/'ENTRADAS PMO'!$D$39 -> 0.70555556 | G21: Cobertura do cachê pelo patrocínio | H21: =Cenarios!$H$12/'ENTRADAS PMO'!$E$39 -> 1.287
A22: Margem de segurança financeira | B22: =Cenarios!$T$10 -> -1.4060865 | D22: Margem de segurança financeira | E22: =Cenarios!$T$11 -> 0.04184055 | G22: Margem de segurança financeira | H22: =Cenarios!$T$12 -> 0.27400891
A23: STATUS | B23: =Cenarios!$V$10 -> VERMELHO | D23: STATUS | E23: =Cenarios!$V$11 -> AMARELO | G23: STATUS | H23: =Cenarios!$V$12 -> VERDE
A24: CLASSIFICAÇÃO | B24: =Cenarios!$W$10 -> NO-GO | D24: CLASSIFICAÇÃO | E24: =Cenarios!$W$11 -> GO COM RESSALVAS | G24: CLASSIFICAÇÃO | H24: =Cenarios!$W$12 -> GO
A26: KPIs EXECUTIVOS (cenário Base / realizado)
A27: Receita projetada (Base) | B27: =Cenarios!$J$11 -> 491026.5 | D27: Receita contratada (patrocínio assinado) | E27: ='ENTRADAS PMO'!$D$22 -> 60000 | G27: Custo projetado (Base / BAC) | H27: =CUSTOS!$C$52 -> 475795.43
A28: Custo contratado | B28: =CUSTOS!$C$54 -> 0 | D28: Resultado projetado (Base) | E28: =Cenarios!$L$11 -> 15231.069 | G28: Margem (Base) | H28: =Cenarios!$M$11 -> 0.031018833
A29: Break-even (ingressos, Base) | B29: =Cenarios!$R$11 -> 2730.7544 | D29: Ingressos vendidos até hoje | E29: =VENDAS!$C$47 -> 0 | G29: Ingressos restantes (meta Base) | H29: =VENDAS!$C$52 -> 2850
A30: Ocupação (Base) | B30: =Cenarios!$D$11 -> 1 | D30: Ticket médio (Base) | E30: =Cenarios!$E$11 -> 106.22456 | G30: Patrocínio contratado | H30: ='ENTRADAS PMO'!$D$22 -> 60000
A31: Patrocínio pipeline | B31: ='ENTRADAS PMO'!$D$23 -> 160000 | D31: Cobertura de patrocínio (esperado/cachê) | E31: =Cenarios!$H$11/'ENTRADAS PMO'!$D$39 -> 0.70555556 | G31: Capital de giro necessário (Base) | H31: ='FLUXO DE CAIXA'!$B$65 -> 12483.96
A32: Contingência disponível | B32: =CUSTOS!F49-CUSTOS!H49 -> 35244.106 | D32: Exposição financeira (custo − patrocínio contratado) | E32: =CUSTOS!$C$52-'ENTRADAS PMO'!$D$22 -> 415795.43 | G32: Forecast final do resultado | H32: =CUSTOS!$C$55 -> 475795.43
A35: INDICADORES DE VENDA
A36: Data atual | B36: =VENDAS!$C$45 -> 46268 | D36: Data do evento | E36: =VENDAS!$C$46 -> 0 | G36: Dias restantes até o evento | H36: =VENDAS!$C$54 -> 0
A37: Ingressos vendidos | B37: =VENDAS!$C$47 -> 0 | D37: % vendido da capacidade Base | E37: =VENDAS!$C$49 -> 0 | G37: Gap para a meta (Base) | H37: =VENDAS!$C$52 -> 2850
A38: Velocidade média de vendas (ingressos/dia) | B38: =VENDAS!$C$55 -> 0 | D38: Venda diária necessária até o evento | E38: =VENDAS!$C$56 -> 0 | G38: Projeção de público final (ritmo atual) | H38: =VENDAS!$C$57 -> 0
A42: RECOMENDAÇÃO PMO (atualiza automaticamente)
A43: STATUS DO PROJETO | B43: =Cenarios!$W$11 -> GO COM RESSALVAS
A44: Resultado Base | B44: =Cenarios!$L$11 -> 15231.069
A45: Margem | B45: =Cenarios!$M$11 -> 0.031018833
A46: Break-even (ingressos) | B46: =Cenarios!$R$11 -> 2730.7544
A47: Patrocínio mínimo adicional necessário | B47: =MAX(0,Cenarios!$U$11-'ENTRADAS PMO'!$D$22) -> 120000
...

Sheet ENTRADAS PMO
A1: PIQUINZADA 2027 | ENTRADAS PMO — PREMISSAS DOS 3 CENÁRIOS
A2: Fonte única de dados (Single Source of Truth). Preencha apenas as células AZUIS. As células CINZAS são calculadas automaticamente.
A4: Bloco | B4: Item | C4: CONSERVADOR | D4: BASE | E4: AGRESSIVO | F4: Observação / Unidade
A5: EVENTO
B6: Capacidade máxima do evento | C6: 2200 | D6: 3000 | E6: 3500 | F6: Público físico máximo suportado pelo espaço/estrutura
B7: Número de cortesias | C7: 120 | D7: 150 | E7: 180 | F7: Convidados, staff, imprensa, permutas (não pagantes)
B8: Ingressos vendidos (pagantes) | C8: =VENDAS!$C$12 -> 1540 | D8: =VENDAS!$C$25 -> 2850 | E8: =VENDAS!$C$38 -> 3150 | F8: Total vendido no plano de lotes (aba VENDAS)
B9: Público total (pagantes + cortesias) | C9: =C8+'ENTRADAS PMO'!$C$7 -> 1660 | D9: =D8+'ENTRADAS PMO'!$D$7 -> 3000 | E9: =E8+'ENTRADAS PMO'!$E$7 -> 3330
B10: % Ocupação da capacidade | C10: =C9/'ENTRADAS PMO'!$C$6 -> 0.75454545 | D10: =D9/'ENTRADAS PMO'!$D$6 -> 1 | E10: =E9/'ENTRADAS PMO'!$E$6 -> 0.95142857
A12: INGRESSOS (resumo — detalhe por lote na aba VENDAS)
B13: Taxa da plataforma de venda (%) | C13: 0.05 | D13: 0.05 | E13: 0.05 | F13: % sobre a receita bruta de ingressos
B14: Taxa de cartão / meios de pagamento (%) | C14: 0.03 | D14: 0.03 | E14: 0.03 | F14: % sobre a receita bruta de ingressos
B15: Tributos incidentes sobre ingressos (%) | C15: 0 | D15: 0 | E15: 0 | F15: Ajustar conforme regime tributário do evento
B16: Ticket médio realizado | C16: =VENDAS!$C$13 -> 80.292208 | D16: =VENDAS!$C$26 -> 106.22456 | E16: =VENDAS!$C$39 -> 111.03175
B17: Receita bruta de ingressos | C17: =VENDAS!$C$14 -> 123650 | D17: =VENDAS!$C$27 -> 302740 | E17: =VENDAS!$C$40 -> 349750
B18: Receita líquida de ingressos | C18: =VENDAS!$C$15 -> 113758 | D18: =VENDAS!$C$28 -> 278520.8 | E18: =VENDAS!$C$41 -> 321770
A20: PATROCÍNIOS (resumo — detalhe por cota na aba PATROCINIOS)
B21: Número de cotas comerciais | C21: =PATROCINIOS!$B$19 -> 10 | D21: =PATROCINIOS!$B$32 -> 12 | E21: =PATROCINIOS!$B$45 -> 16
B22: Patrocínio contratado (assinado) | C22: =PATROCINIOS!$B$20 -> 0 | D22: =PATROCINIOS!$B$33 -> 60000 | E22: =PATROCINIOS!$B$46 -> 198000
B23: Patrocínio em negociação/pipeline | C23: =PATROCINIOS!$B$21 -> 174200 | D23: =PATROCINIOS!$B$34 -> 160000 | E23: =PATROCINIOS!$B$47 -> 150000
B24: Patrocínio esperado (ponderado por probabilidade) | C24: =PATROCINIOS!$B$22 -> 47820 | D24: =PATROCINIOS!$B$35 -> 127000 | E24: =PATROCINIOS!$B$48 -> 257400
B25: Cobertura do cachê da atração pelo patrocínio esperado | C25: =C24/'ENTRADAS PMO'!$C$39 -> 0.298875 | D25: =D24/'ENTRADAS PMO'!$D$39 -> 0.70555556 | E25: =E24/'ENTRADAS PMO'!$E$39 -> 1.287
A27: CONSUMO / BAR / ATIVAÇÕES
B28: Consumo médio bruto por pessoa | C28: 55 | D28: 70 | E28: 80 | F28: Ticket médio de bar/ativações por participante
B29: Custo operacional do consumo (% da receita bruta) | C29: 0.6 | D29: 0.5714 | E29: 0.5625 | F29: Custo de mercadoria, equipe e operação do bar/ativações
B30: Margem líquida por pessoa | C30: ='ENTRADAS PMO'!$C$28*(1-'ENTRADAS PMO'!$C$29) -> 22 | D30: ='ENTRADAS PMO'!$D$28*(1-'ENTRADAS PMO'!$D$29) -> 30.002 | E30: ='ENTRADAS PMO'!$E$28*(1-'ENTRADAS PMO'!$E$29) -> 35
B31: Receita bruta de consumo/ativações | C31: ='ENTRADAS PMO'!$C$28*C8 -> 84700 | D31: ='ENTRADAS PMO'!$D$28*D8 -> 199500 | E31: ='ENTRADAS PMO'!$E$28*E8 -> 252000
B32: Custo operacional de consumo/ativações | C32: =C31*'ENTRADAS PMO'!$C$29 -> 50820 | D32: =D31*'ENTRADAS PMO'!$D$29 -> 113994.3 | E32: =E31*'ENTRADAS PMO'!$E$29 -> 141750
B33: Receita líquida de consumo/ativações | C33: =C30*C8 -> 33880 | D33: =D30*D8 -> 85505.7 | E33: =E30*E8 -> 110250
A35: OUTRAS RECEITAS
B36: Outras receitas (merchandising, permutas ativas, etc.) | C36: 0 | D36: 0 | E36: 0 | F36: Receitas não classificadas acima
A38: ATRAÇÕES
B39: Cachê atração principal | C39: 160000 | D39: 180000 | E39: 200000
B40: Cachês das atrações de apoio | C40: 8000 | D40: 10000 | E40: 14000
B41: DJs | C41: 6000 | D41: 7500 | E41: 10500
B42: Banda de abertura | C42: 4000 | D42: 5000 | E42: 7000
B43: Participações especiais | C43: 2000 | D43: 2500 | E43: 3500
B44: Subtotal Atrações | C44: =SUM(C39:C43) -> 180000 | D44: =SUM(D39:D43) -> 205000 | E44: =SUM(E39:E43) -> 235000
A46: ESTRUTURA
B47: Palco | C47: 22400 | D47: 25200 | E47: 30800
...

Sheet VENDAS
A1: PIQUINZADA 2027 | VENDAS — PLANO DE LOTES E ACOMPANHAMENTO
A2: Fonte única dos dados de ingressos. Preencha a quantidade e o preço de cada lote em cada cenário.
A4: CENÁRIO CONSERVADOR
A5: Lote | B5: Preço (R$) | C5: Qtd. planejada | D5: % mix | E5: Receita bruta | F5: Taxa plataforma | G5: Taxa cartão | H5: Tributos | I5: Receita líquida | J5: Conversão acum. capacidade
A6: Pré-venda | B6: 60 | C6: 300 | D6: =C6/SUM($C$6:$C$10) -> 0.19480519 | E6: =B6*C6 -> 18000 | F6: =E6*'ENTRADAS PMO'!$C$13 -> 900 | G6: =E6*'ENTRADAS PMO'!$C$14 -> 540 | H6: =E6*'ENTRADAS PMO'!$C$15 -> 0 | I6: =E6-F6-G6-H6 -> 16560 | J6: =SUM($C$6:C6)/'ENTRADAS PMO'!$C$6 -> 0.13636364
A7: 1º lote | B7: 75 | C7: 550 | D7: =C7/SUM($C$6:$C$10) -> 0.35714286 | E7: =B7*C7 -> 41250 | F7: =E7*'ENTRADAS PMO'!$C$13 -> 2062.5 | G7: =E7*'ENTRADAS PMO'!$C$14 -> 1237.5 | H7: =E7*'ENTRADAS PMO'!$C$15 -> 0 | I7: =E7-F7-G7-H7 -> 37950 | J7: =SUM($C$6:C7)/'ENTRADAS PMO'!$C$6 -> 0.38636364
A8: 2º lote | B8: 90 | C8: 500 | D8: =C8/SUM($C$6:$C$10) -> 0.32467532 | E8: =B8*C8 -> 45000 | F8: =E8*'ENTRADAS PMO'!$C$13 -> 2250 | G8: =E8*'ENTRADAS PMO'!$C$14 -> 1350 | H8: =E8*'ENTRADAS PMO'!$C$15 -> 0 | I8: =E8-F8-G8-H8 -> 41400 | J8: =SUM($C$6:C8)/'ENTRADAS PMO'!$C$6 -> 0.61363636
A9: 3º lote | B9: 100 | C9: 150 | D9: =C9/SUM($C$6:$C$10) -> 0.097402597 | E9: =B9*C9 -> 15000 | F9: =E9*'ENTRADAS PMO'!$C$13 -> 750 | G9: =E9*'ENTRADAS PMO'!$C$14 -> 450 | H9: =E9*'ENTRADAS PMO'!$C$15 -> 0 | I9: =E9-F9-G9-H9 -> 13800 | J9: =SUM($C$6:C9)/'ENTRADAS PMO'!$C$6 -> 0.68181818
A10: Último lote | B10: 110 | C10: 40 | D10: =C10/SUM($C$6:$C$10) -> 0.025974026 | E10: =B10*C10 -> 4400 | F10: =E10*'ENTRADAS PMO'!$C$13 -> 220 | G10: =E10*'ENTRADAS PMO'!$C$14 -> 132 | H10: =E10*'ENTRADAS PMO'!$C$15 -> 0 | I10: =E10-F10-G10-H10 -> 4048 | J10: =SUM($C$6:C10)/'ENTRADAS PMO'!$C$6 -> 0.7
A12: Ingressos planejados (pagantes) | C12: =SUM(C6:C10) -> 1540
A13: Ticket médio planejado | C13: =SUM(E6:E10)/SUM(C6:C10) -> 80.292208
A14: Receita bruta planejada | C14: =SUM(E6:E10) -> 123650
A15: Receita líquida planejada | C15: =SUM(I6:I10) -> 113758
A17: CENÁRIO BASE
A18: Lote | B18: Preço (R$) | C18: Qtd. planejada | D18: % mix | E18: Receita bruta | F18: Taxa plataforma | G18: Taxa cartão | H18: Tributos | I18: Receita líquida | J18: Conversão acum. capacidade
A19: Pré-venda | B19: 70 | C19: 330 | D19: =C19/SUM($C$19:$C$23) -> 0.11578947 | E19: =B19*C19 -> 23100 | F19: =E19*'ENTRADAS PMO'!$D$13 -> 1155 | G19: =E19*'ENTRADAS PMO'!$D$14 -> 693 | H19: =E19*'ENTRADAS PMO'!$D$15 -> 0 | I19: =E19-F19-G19-H19 -> 21252 | J19: =SUM($C$19:C19)/'ENTRADAS PMO'!$D$6 -> 0.11
A20: 1º lote | B20: 85 | C20: 620 | D20: =C20/SUM($C$19:$C$23) -> 0.21754386 | E20: =B20*C20 -> 52700 | F20: =E20*'ENTRADAS PMO'!$D$13 -> 2635 | G20: =E20*'ENTRADAS PMO'!$D$14 -> 1581 | H20: =E20*'ENTRADAS PMO'!$D$15 -> 0 | I20: =E20-F20-G20-H20 -> 48484 | J20: =SUM($C$19:C20)/'ENTRADAS PMO'!$D$6 -> 0.31666667
A21: 2º lote | B21: 105 | C21: 800 | D21: =C21/SUM($C$19:$C$23) -> 0.28070175 | E21: =B21*C21 -> 84000 | F21: =E21*'ENTRADAS PMO'!$D$13 -> 4200 | G21: =E21*'ENTRADAS PMO'!$D$14 -> 2520 | H21: =E21*'ENTRADAS PMO'!$D$15 -> 0 | I21: =E21-F21-G21-H21 -> 77280 | J21: =SUM($C$19:C21)/'ENTRADAS PMO'!$D$6 -> 0.58333333
A22: 3º lote | B22: 122 | C22: 720 | D22: =C22/SUM($C$19:$C$23) -> 0.25263158 | E22: =B22*C22 -> 87840 | F22: =E22*'ENTRADAS PMO'!$D$13 -> 4392 | G22: =E22*'ENTRADAS PMO'!$D$14 -> 2635.2 | H22: =E22*'ENTRADAS PMO'!$D$15 -> 0 | I22: =E22-F22-G22-H22 -> 80812.8 | J22: =SUM($C$19:C22)/'ENTRADAS PMO'!$D$6 -> 0.82333333
A23: Último lote | B23: 145 | C23: 380 | D23: =C23/SUM($C$19:$C$23) -> 0.13333333 | E23: =B23*C23 -> 55100 | F23: =E23*'ENTRADAS PMO'!$D$13 -> 2755 | G23: =E23*'ENTRADAS PMO'!$D$14 -> 1653 | H23: =E23*'ENTRADAS PMO'!$D$15 -> 0 | I23: =E23-F23-G23-H23 -> 50692 | J23: =SUM($C$19:C23)/'ENTRADAS PMO'!$D$6 -> 0.95
A25: Ingressos planejados (pagantes) | C25: =SUM(C19:C23) -> 2850
A26: Ticket médio planejado | C26: =SUM(E19:E23)/SUM(C19:C23) -> 106.22456
A27: Receita bruta planejada | C27: =SUM(E19:E23) -> 302740
A28: Receita líquida planejada | C28: =SUM(I19:I23) -> 278520.8
A30: CENÁRIO AGRESSIVO
A31: Lote | B31: Preço (R$) | C31: Qtd. planejada | D31: % mix | E31: Receita bruta | F31: Taxa plataforma | G31: Taxa cartão | H31: Tributos | I31: Receita líquida | J31: Conversão acum. capacidade
A32: Pré-venda | B32: 80 | C32: 450 | D32: =C32/SUM($C$32:$C$36) -> 0.14285714 | E32: =B32*C32 -> 36000 | F32: =E32*'ENTRADAS PMO'!$E$13 -> 1800 | G32: =E32*'ENTRADAS PMO'!$E$14 -> 1080 | H32: =E32*'ENTRADAS PMO'!$E$15 -> 0 | I32: =E32-F32-G32-H32 -> 33120 | J32: =SUM($C$32:C32)/'ENTRADAS PMO'!$E$6 -> 0.12857143
A33: 1º lote | B33: 95 | C33: 800 | D33: =C33/SUM($C$32:$C$36) -> 0.25396825 | E33: =B33*C33 -> 76000 | F33: =E33*'ENTRADAS PMO'!$E$13 -> 3800 | G33: =E33*'ENTRADAS PMO'!$E$14 -> 2280 | H33: =E33*'ENTRADAS PMO'!$E$15 -> 0 | I33: =E33-F33-G33-H33 -> 69920 | J33: =SUM($C$32:C33)/'ENTRADAS PMO'!$E$6 -> 0.35714286
A34: 2º lote | B34: 115 | C34: 950 | D34: =C34/SUM($C$32:$C$36) -> 0.3015873 | E34: =B34*C34 -> 109250 | F34: =E34*'ENTRADAS PMO'!$E$13 -> 5462.5 | G34: =E34*'ENTRADAS PMO'!$E$14 -> 3277.5 | H34: =E34*'ENTRADAS PMO'!$E$15 -> 0 | I34: =E34-F34-G34-H34 -> 100510 | J34: =SUM($C$32:C34)/'ENTRADAS PMO'!$E$6 -> 0.62857143
A35: 3º lote | B35: 130 | C35: 700 | D35: =C35/SUM($C$32:$C$36) -> 0.22222222 | E35: =B35*C35 -> 91000 | F35: =E35*'ENTRADAS PMO'!$E$13 -> 4550 | G35: =E35*'ENTRADAS PMO'!$E$14 -> 2730 | H35: =E35*'ENTRADAS PMO'!$E$15 -> 0 | I35: =E35-F35-G35-H35 -> 83720 | J35: =SUM($C$32:C35)/'ENTRADAS PMO'!$E$6 -> 0.82857143
A36: Último lote | B36: 150 | C36: 250 | D36: =C36/SUM($C$32:$C$36) -> 0.079365079 | E36: =B36*C36 -> 37500 | F36: =E36*'ENTRADAS PMO'!$E$13 -> 1875 | G36: =E36*'ENTRADAS PMO'!$E$14 -> 1125 | H36: =E36*'ENTRADAS PMO'!$E$15 -> 0 | I36: =E36-F36-G36-H36 -> 34500 | J36: =SUM($C$32:C36)/'ENTRADAS PMO'!$E$6 -> 0.9
A38: Ingressos planejados (pagantes) | C38: =SUM(C32:C36) -> 3150
A39: Ticket médio planejado | C39: =SUM(E32:E36)/SUM(C32:C36) -> 111.03175
A40: Receita bruta planejada | C40: =SUM(E32:E36) -> 349750
A41: Receita líquida planejada | C41: =SUM(I32:I36) -> 321770
A43: ACOMPANHAMENTO DE VENDAS REALIZADO (indicadores de venda)
A44: Data de início das vendas
A45: Data atual | C45: =TODAY() -> 46268
A46: Data do evento
A47: Ingressos vendidos até hoje | C47: 0
...

Sheet PATROCINIOS
A1: PIQUINZADA 2027 | PATROCÍNIOS — PIPELINE COMERCIAL
A2: Fonte única dos dados de patrocínio. Estágio define a probabilidade de fechamento automaticamente (tabela abaixo é editável).
A4: PROBABILIDADE PADRÃO POR ESTÁGIO (editável)
A5: Estágio | B5: Probabilidade
A6: Contratado | B6: 1
A7: Proposta Enviada | B7: 0.5
A8: Negociação | B8: 0.3
A9: Prospecção | B9: 0.15
A11: CENÁRIO CONSERVADOR
A12: Cota | B12: Valor unitário | C12: Qtd. alvo | D12: Estágio | E12: Probabilidade | F12: Receita alvo | G12: Receita ponderada | H12: Contrapartida-chave | I12: Perfil de patrocinador
A13: Naming / Apresenta | B13: 51000 | C13: 1 | D13: Negociação | E13: =INDEX($B$6:$B$9,MATCH(D13,$A$6:$A$9,0)) -> 0.3 | F13: =B13*C13 -> 51000 | G13: =F13*E13 -> 15300 | H13: Marca no nome do evento + palco + mídia principal | I13: Banco, bebida, varejo, telecom
A14: Master | B14: 29800 | C14: 2 | D14: Negociação | E14: =INDEX($B$6:$B$9,MATCH(D14,$A$6:$A$9,0)) -> 0.3 | F14: =B14*C14 -> 59600 | G14: =F14*E14 -> 17880 | H14: Alta exposição + ativações + camarote | I14: Bebidas, varejo, construção
A15: Ouro | B15: 17000 | C15: 2 | D15: Negociação | E15: =INDEX($B$6:$B$9,MATCH(D15,$A$6:$A$9,0)) -> 0.3 | F15: =B15*C15 -> 34000 | G15: =F15*E15 -> 10200 | H15: Logo premium + ativações + conteúdo | I15: Empresas regionais e nacionais
A16: Prata | B16: 8500 | C16: 2 | D16: Prospecção | E16: =INDEX($B$6:$B$9,MATCH(D16,$A$6:$A$9,0)) -> 0.15 | F16: =B16*C16 -> 17000 | G16: =F16*E16 -> 2550 | H16: Logo + espaço de ativação | I16: Comércio e serviços
A17: Apoio | B17: 4200 | C17: 3 | D17: Prospecção | E17: =INDEX($B$6:$B$9,MATCH(D17,$A$6:$A$9,0)) -> 0.15 | F17: =B17*C17 -> 12600 | G17: =F17*E17 -> 1890 | H17: Logo em peças selecionadas | I17: Parceiros locais
A19: Nº de cotas comerciais | B19: =SUM(C13:C17) -> 10
A20: Patrocínio contratado (assinado) | B20: =SUMIFS(F13:F17,D13:D17,"Contratado") -> 0
A21: Patrocínio em negociação/pipeline | B21: =SUMIFS(F13:F17,D13:D17,"<>Contratado") -> 174200
A22: Receita ponderada pela probabilidade (esperado) | B22: =SUM(G13:G17) -> 47820
A24: CENÁRIO BASE
A25: Cota | B25: Valor unitário | C25: Qtd. alvo | D25: Estágio | E25: Probabilidade | F25: Receita alvo | G25: Receita ponderada | H25: Contrapartida-chave | I25: Perfil de patrocinador
A26: Naming / Apresenta | B26: 60000 | C26: 1 | D26: Contratado | E26: =INDEX($B$6:$B$9,MATCH(D26,$A$6:$A$9,0)) -> 1 | F26: =B26*C26 -> 60000 | G26: =F26*E26 -> 60000 | H26: Marca no nome do evento + palco + mídia principal | I26: Banco, bebida, varejo, telecom
A27: Master | B27: 35000 | C27: 2 | D27: Proposta Enviada | E27: =INDEX($B$6:$B$9,MATCH(D27,$A$6:$A$9,0)) -> 0.5 | F27: =B27*C27 -> 70000 | G27: =F27*E27 -> 35000 | H27: Alta exposição + ativações + camarote | I27: Bebidas, varejo, construção
A28: Ouro | B28: 20000 | C28: 2 | D28: Proposta Enviada | E28: =INDEX($B$6:$B$9,MATCH(D28,$A$6:$A$9,0)) -> 0.5 | F28: =B28*C28 -> 40000 | G28: =F28*E28 -> 20000 | H28: Logo premium + ativações + conteúdo | I28: Empresas regionais e nacionais
A29: Prata | B29: 10000 | C29: 3 | D29: Negociação | E29: =INDEX($B$6:$B$9,MATCH(D29,$A$6:$A$9,0)) -> 0.3 | F29: =B29*C29 -> 30000 | G29: =F29*E29 -> 9000 | H29: Logo + espaço de ativação | I29: Comércio e serviços
A30: Apoio | B30: 5000 | C30: 4 | D30: Prospecção | E30: =INDEX($B$6:$B$9,MATCH(D30,$A$6:$A$9,0)) -> 0.15 | F30: =B30*C30 -> 20000 | G30: =F30*E30 -> 3000 | H30: Logo em peças selecionadas | I30: Parceiros locais
A32: Nº de cotas comerciais | B32: =SUM(C26:C30) -> 12
A33: Patrocínio contratado (assinado) | B33: =SUMIFS(F26:F30,D26:D30,"Contratado") -> 60000
A34: Patrocínio em negociação/pipeline | B34: =SUMIFS(F26:F30,D26:D30,"<>Contratado") -> 160000
A35: Receita ponderada pela probabilidade (esperado) | B35: =SUM(G26:G30) -> 127000
A37: CENÁRIO AGRESSIVO
A38: Cota | B38: Valor unitário | C38: Qtd. alvo | D38: Estágio | E38: Probabilidade | F38: Receita alvo | G38: Receita ponderada | H38: Contrapartida-chave | I38: Perfil de patrocinador
A39: Naming / Apresenta | B39: 72000 | C39: 1 | D39: Contratado | E39: =INDEX($B$6:$B$9,MATCH(D39,$A$6:$A$9,0)) -> 1 | F39: =B39*C39 -> 72000 | G39: =F39*E39 -> 72000 | H39: Marca no nome do evento + palco + mídia principal | I39: Banco, bebida, varejo, telecom
A40: Master | B40: 42000 | C40: 3 | D40: Contratado | E40: =INDEX($B$6:$B$9,MATCH(D40,$A$6:$A$9,0)) -> 1 | F40: =B40*C40 -> 126000 | G40: =F40*E40 -> 126000 | H40: Alta exposição + ativações + camarote | I40: Bebidas, varejo, construção
A41: Ouro | B41: 24000 | C41: 3 | D41: Proposta Enviada | E41: =INDEX($B$6:$B$9,MATCH(D41,$A$6:$A$9,0)) -> 0.5 | F41: =B41*C41 -> 72000 | G41: =F41*E41 -> 36000 | H41: Logo premium + ativações + conteúdo | I41: Empresas regionais e nacionais
A42: Prata | B42: 12000 | C42: 4 | D42: Negociação | E42: =INDEX($B$6:$B$9,MATCH(D42,$A$6:$A$9,0)) -> 0.3 | F42: =B42*C42 -> 48000 | G42: =F42*E42 -> 14400 | H42: Logo + espaço de ativação | I42: Comércio e serviços
A43: Apoio | B43: 6000 | C43: 5 | D43: Negociação | E43: =INDEX($B$6:$B$9,MATCH(D43,$A$6:$A$9,0)) -> 0.3 | F43: =B43*C43 -> 30000 | G43: =F43*E43 -> 9000 | H43: Logo em peças selecionadas | I43: Parceiros locais
A45: Nº de cotas comerciais | B45: =SUM(C39:C43) -> 16
A46: Patrocínio contratado (assinado) | B46: =SUMIFS(F39:F43,D39:D43,"Contratado") -> 198000
A47: Patrocínio em negociação/pipeline | B47: =SUMIFS(F39:F43,D39:D43,"<>Contratado") -> 150000
...

Sheet CUSTOS
A1: PIQUINZADA 2027 | CUSTOS — REGISTRO PMO (BASELINE = CENÁRIO BASE)
A2: Cada linha puxa o Orçamento inicial da aba ENTRADAS PMO (coluna Base). Preencha apenas as colunas azuis conforme a contratação evolui.
A4: Categoria (Grupo) | B4: Subcategoria | C4: Fornecedor | D4: Descrição | E4: Orçamento inicial | F4: Orçamento aprovado | G4: Valor contratado | H4: Valor pago | I4: Saldo a pagar | J4: Data prevista | K4: Data pagamento | L4: Status | M4: Responsável | N4: Observação | O4: EAC do item
A5: Atrações | B5: Cachê atração principal | C5: DJ Marcelinho / Assessoria Ltda. | E5: ='ENTRADAS PMO'!$D$39 -> 180000 | F5: =E5 -> 180000 | G5: 0 | H5: 0 | I5: =G5-H5 -> 0 | J5: 2027-06-01 | L5: Contratado | M5: Comercial | O5: =IF(F5>=G5,F5,G5) -> 180000
A6: Atrações | B6: Cachês das atrações de apoio | E6: ='ENTRADAS PMO'!$D$40 -> 10000 | F6: =E6 -> 10000 | G6: 0 | H6: 0 | I6: =G6-H6 -> 0 | L6: Não iniciado | O6: =IF(F6>=G6,F6,G6) -> 10000
A7: Atrações | B7: DJs | E7: ='ENTRADAS PMO'!$D$41 -> 7500 | F7: =E7 -> 7500 | G7: 0 | H7: 0 | I7: =G7-H7 -> 0 | L7: Não iniciado | O7: =IF(F7>=G7,F7,G7) -> 7500
A8: Atrações | B8: Banda de abertura | E8: ='ENTRADAS PMO'!$D$42 -> 5000 | F8: =E8 -> 5000 | G8: 0 | H8: 0 | I8: =G8-H8 -> 0 | L8: Não iniciado | O8: =IF(F8>=G8,F8,G8) -> 5000
A9: Atrações | B9: Participações especiais | E9: ='ENTRADAS PMO'!$D$43 -> 2500 | F9: =E9 -> 2500 | G9: 0 | H9: 0 | I9: =G9-H9 -> 0 | L9: Não iniciado | O9: =IF(F9>=G9,F9,G9) -> 2500
A10: Estrutura | B10: Palco | E10: ='ENTRADAS PMO'!$D$47 -> 25200 | F10: =E10 -> 25200 | G10: 0 | H10: 0 | I10: =G10-H10 -> 0 | L10: Em cotação | M10: Produção | O10: =IF(F10>=G10,F10,G10) -> 25200
A11: Estrutura | B11: Som | E11: ='ENTRADAS PMO'!$D$48 -> 16200 | F11: =E11 -> 16200 | G11: 0 | H11: 0 | I11: =G11-H11 -> 0 | L11: Em cotação | M11: Produção | O11: =IF(F11>=G11,F11,G11) -> 16200
A12: Estrutura | B12: Iluminação | E12: ='ENTRADAS PMO'!$D$49 -> 12600 | F12: =E12 -> 12600 | G12: 0 | H12: 0 | I12: =G12-H12 -> 0 | L12: Não iniciado | O12: =IF(F12>=G12,F12,G12) -> 12600
A13: Estrutura | B13: Painel de LED | E13: ='ENTRADAS PMO'!$D$50 -> 10800 | F13: =E13 -> 10800 | G13: 0 | H13: 0 | I13: =G13-H13 -> 0 | L13: Não iniciado | O13: =IF(F13>=G13,F13,G13) -> 10800
A14: Estrutura | B14: Gerador | E14: ='ENTRADAS PMO'!$D$51 -> 8100 | F14: =E14 -> 8100 | G14: 0 | H14: 0 | I14: =G14-H14 -> 0 | L14: Não iniciado | O14: =IF(F14>=G14,F14,G14) -> 8100
A15: Estrutura | B15: Banheiros químicos | E15: ='ENTRADAS PMO'!$D$52 -> 5400 | F15: =E15 -> 5400 | G15: 0 | H15: 0 | I15: =G15-H15 -> 0 | L15: Não iniciado | O15: =IF(F15>=G15,F15,G15) -> 5400
A16: Estrutura | B16: Gradil / contenção | E16: ='ENTRADAS PMO'!$D$53 -> 4500 | F16: =E16 -> 4500 | G16: 0 | H16: 0 | I16: =G16-H16 -> 0 | L16: Não iniciado | O16: =IF(F16>=G16,F16,G16) -> 4500
A17: Estrutura | B17: Tendas | E17: ='ENTRADAS PMO'!$D$54 -> 3600 | F17: =E17 -> 3600 | G17: 0 | H17: 0 | I17: =G17-H17 -> 0 | L17: Não iniciado | O17: =IF(F17>=G17,F17,G17) -> 3600
A18: Estrutura | B18: Mobiliário | E18: ='ENTRADAS PMO'!$D$55 -> 1800 | F18: =E18 -> 1800 | G18: 0 | H18: 0 | I18: =G18-H18 -> 0 | L18: Não iniciado | O18: =IF(F18>=G18,F18,G18) -> 1800
A19: Estrutura | B19: Estrutura de camarote | E19: ='ENTRADAS PMO'!$D$56 -> 900 | F19: =E19 -> 900 | G19: 0 | H19: 0 | I19: =G19-H19 -> 0 | L19: Não iniciado | O19: =IF(F19>=G19,F19,G19) -> 900
A20: Estrutura | B20: Decoração | E20: ='ENTRADAS PMO'!$D$57 -> 900 | F20: =E20 -> 900 | G20: 0 | H20: 0 | I20: =G20-H20 -> 0 | L20: Não iniciado | O20: =IF(F20>=G20,F20,G20) -> 900
A21: Segurança | B21: Segurança | E21: ='ENTRADAS PMO'!$D$61 -> 14000 | F21: =E21 -> 14000 | G21: 0 | H21: 0 | I21: =G21-H21 -> 0 | L21: Não iniciado | O21: =IF(F21>=G21,F21,G21) -> 14000
A22: Segurança | B22: Brigadistas | E22: ='ENTRADAS PMO'!$D$62 -> 3500 | F22: =E22 -> 3500 | G22: 0 | H22: 0 | I22: =G22-H22 -> 0 | L22: Não iniciado | O22: =IF(F22>=G22,F22,G22) -> 3500
A23: Segurança | B23: Bombeiro civil | E23: ='ENTRADAS PMO'!$D$63 -> 2500 | F23: =E23 -> 2500 | G23: 0 | H23: 0 | I23: =G23-H23 -> 0 | L23: Não iniciado | O23: =IF(F23>=G23,F23,G23) -> 2500
A24: Segurança | B24: Ambulância / SAMU privado | E24: ='ENTRADAS PMO'!$D$64 -> 2500 | F24: =E24 -> 2500 | G24: 0 | H24: 0 | I24: =G24-H24 -> 0 | L24: Não iniciado | O24: =IF(F24>=G24,F24,G24) -> 2500
A25: Produção | B25: Limpeza | E25: ='ENTRADAS PMO'!$D$65 -> 4500 | F25: =E25 -> 4500 | G25: 0 | H25: 0 | I25: =G25-H25 -> 0 | L25: Não iniciado | O25: =IF(F25>=G25,F25,G25) -> 4500
A26: Produção | B26: Recepção / credenciamento | E26: ='ENTRADAS PMO'!$D$66 -> 3000 | F26: =E26 -> 3000 | G26: 0 | H26: 0 | I26: =G26-H26 -> 0 | L26: Não iniciado | O26: =IF(F26>=G26,F26,G26) -> 3000
A27: Produção | B27: Produção geral | E27: ='ENTRADAS PMO'!$D$67 -> 11000 | F27: =E27 -> 11000 | G27: 0 | H27: 0 | I27: =G27-H27 -> 0 | L27: Não iniciado | O27: =IF(F27>=G27,F27,G27) -> 11000
A28: Produção | B28: Equipe de apoio | E28: ='ENTRADAS PMO'!$D$68 -> 4500 | F28: =E28 -> 4500 | G28: 0 | H28: 0 | I28: =G28-H28 -> 0 | L28: Não iniciado | O28: =IF(F28>=G28,F28,G28) -> 4500
A29: Licenças | B29: Licenças e alvarás | E29: ='ENTRADAS PMO'!$D$69 -> 2000 | F29: =E29 -> 2000 | G29: 0 | H29: 0 | I29: =G29-H29 -> 0 | L29: Não iniciado | O29: =IF(F29>=G29,F29,G29) -> 2000
A30: Licenças | B30: ECAD | E30: ='ENTRADAS PMO'!$D$70 -> 1500 | F30: =E30 -> 1500 | G30: 0 | H30: 0 | I30: =G30-H30 -> 0 | L30: Não iniciado | O30: =IF(F30>=G30,F30,G30) -> 1500
A31: Licenças | B31: Seguro do evento | E31: ='ENTRADAS PMO'!$D$71 -> 1000 | F31: =E31 -> 1000 | G31: 0 | H31: 0 | I31: =G31-H31 -> 0 | L31: Não iniciado | O31: =IF(F31>=G31,F31,G31) -> 1000
A32: Marketing | B32: Tráfego pago | E32: ='ENTRADAS PMO'!$D$75 -> 11200 | F32: =E32 -> 11200 | G32: 0 | H32: 0 | I32: =G32-H32 -> 0 | L32: Não iniciado | O32: =IF(F32>=G32,F32,G32) -> 11200
A33: Marketing | B33: Influenciadores | E33: ='ENTRADAS PMO'!$D$76 -> 5600 | F33: =E33 -> 5600 | G33: 0 | H33: 0 | I33: =G33-H33 -> 0 | L33: Não iniciado | O33: =IF(F33>=G33,F33,G33) -> 5600
A34: Marketing | B34: Designer | E34: ='ENTRADAS PMO'!$D$77 -> 3500 | F34: =E34 -> 3500 | G34: 0 | H34: 0 | I34: =G34-H34 -> 0 | L34: Não iniciado | O34: =IF(F34>=G34,F34,G34) -> 3500
A35: Marketing | B35: Fotografia | E35: ='ENTRADAS PMO'!$D$78 -> 3500 | F35: =E35 -> 3500 | G35: 0 | H35: 0 | I35: =G35-H35 -> 0 | L35: Não iniciado | O35: =IF(F35>=G35,F35,G35) -> 3500
A36: Marketing | B36: Filmagem | E36: ='ENTRADAS PMO'!$D$79 -> 3500 | F36: =E36 -> 3500 | G36: 0 | H36: 0 | I36: =G36-H36 -> 0 | L36: Não iniciado | O36: =IF(F36>=G36,F36,G36) -> 3500
A37: Marketing | B37: Assessoria de imprensa | E37: ='ENTRADAS PMO'!$D$80 -> 2800 | F37: =E37 -> 2800 | G37: 0 | H37: 0 | I37: =G37-H37 -> 0 | L37: Não iniciado | O37: =IF(F37>=G37,F37,G37) -> 2800
A38: Marketing | B38: Mídia (rádio/OOH) | E38: ='ENTRADAS PMO'!$D$81 -> 2800 | F38: =E38 -> 2800 | G38: 0 | H38: 0 | I38: =G38-H38 -> 0 | L38: Não iniciado | O38: =IF(F38>=G38,F38,G38) -> 2800
A39: Marketing | B39: Impressos | E39: ='ENTRADAS PMO'!$D$82 -> 1400 | F39: =E39 -> 1400 | G39: 0 | H39: 0 | I39: =G39-H39 -> 0 | L39: Não iniciado | O39: =IF(F39>=G39,F39,G39) -> 1400
A40: Marketing | B40: Comunicação visual | E40: ='ENTRADAS PMO'!$D$83 -> 700 | F40: =E40 -> 700 | G40: 0 | H40: 0 | I40: =G40-H40 -> 0 | L40: Não iniciado | O40: =IF(F40>=G40,F40,G40) -> 700
A41: Logística | B41: Transporte | E41: ='ENTRADAS PMO'!$D$87 -> 8400 | F41: =E41 -> 8400 | G41: 0 | H41: 0 | I41: =G41-H41 -> 0 | L41: Não iniciado | O41: =IF(F41>=G41,F41,G41) -> 8400
...

Sheet Cenarios
A1: PIQUINZADA 2027 | MOTOR DE CÁLCULO DOS CENÁRIOS
A2: Aba de cálculo — não editar diretamente. Todos os valores derivam de ENTRADAS PMO, VENDAS, PATROCINIOS e CUSTOS.
A4: PARÂMETROS DE CLASSIFICAÇÃO (editável)
A5: Margem mínima p/ status VERDE | B5: 0.1
A6: Margem de segurança mínima p/ status VERDE | B6: 0.15
A7: Margem abaixo da qual o status é VERMELHO | B7: 0
A9: Cenário | B9: Pagantes | C9: Público total | D9: % Ocupação | E9: Ticket médio | F9: Receita ingressos (líq.) | G9: Receita consumo (líq.) | H9: Patrocínio esperado | I9: Outras receitas | J9: RECEITA TOTAL | K9: CUSTO TOTAL | L9: RESULTADO | M9: MARGEM | N9: Receita/participante | O9: Custo/participante | P9: Contribuição/pagante | Q9: BE ingressos s/ patrocínio | R9: BE ingressos c/ patrocínio | S9: % capacidade p/ BE | T9: Margem de segurança | U9: Patrocínio mínimo p/ cachê | V9: Status | W9: Classificação executiva
A10: Conservador | B10: ='ENTRADAS PMO'!$C$8 -> 1540 | C10: ='ENTRADAS PMO'!$C$9 -> 1660 | D10: ='ENTRADAS PMO'!$C$10 -> 0.75454545 | E10: ='ENTRADAS PMO'!$C$16 -> 80.292208 | F10: ='ENTRADAS PMO'!$C$18 -> 113758 | G10: ='ENTRADAS PMO'!$C$33 -> 33880 | H10: ='ENTRADAS PMO'!$C$24 -> 47820 | I10: ='ENTRADAS PMO'!$C$36 -> 0 | J10: =SUM(F10:I10) -> 195458 | K10: ='ENTRADAS PMO'!$C$107 -> 403049.8 | L10: =J10-K10 -> -207591.8 | M10: =IFERROR(L10/J10,0) -> -1.0620788 | N10: =IFERROR(J10/B10,0) -> 126.92078 | O10: =IFERROR(K10/B10,0) -> 261.72065 | P10: =IFERROR(F10/B10,0)+'ENTRADAS PMO'!$C$30 -> 95.868831 | Q10: =IFERROR(K10/P10,0) -> 4204.1798 | R10: =MAX(0,IFERROR((K10-H10-I10)/P10,0)) -> 3705.3733 | S10: =IFERROR(R10/'ENTRADAS PMO'!$C$6,0) -> 1.6842606 | T10: =IFERROR((B10-R10)/B10,0) -> -1.4060865 | U10: ='ENTRADAS PMO'!$C$39 -> 160000 | V10: =IF(AND(M10>=Cenarios!$B$5,T10>=Cenarios!$B$6),"VERDE",IF(OR(M10<Cenarios!$B$7,T10<0),"VERMELHO","AMARELO")) -> VERMELHO | W10: =IF(V10="VERDE","GO",IF(V10="VERMELHO","NO-GO","GO COM RESSALVAS")) -> NO-GO
A11: Base | B11: ='ENTRADAS PMO'!$D$8 -> 2850 | C11: ='ENTRADAS PMO'!$D$9 -> 3000 | D11: ='ENTRADAS PMO'!$D$10 -> 1 | E11: ='ENTRADAS PMO'!$D$16 -> 106.22456 | F11: ='ENTRADAS PMO'!$D$18 -> 278520.8 | G11: ='ENTRADAS PMO'!$D$33 -> 85505.7 | H11: ='ENTRADAS PMO'!$D$24 -> 127000 | I11: ='ENTRADAS PMO'!$D$36 -> 0 | J11: =SUM(F11:I11) -> 491026.5 | K11: ='ENTRADAS PMO'!$D$107 -> 475795.43 | L11: =J11-K11 -> 15231.069 | M11: =IFERROR(L11/J11,0) -> 0.031018833 | N11: =IFERROR(J11/B11,0) -> 172.29 | O11: =IFERROR(K11/B11,0) -> 166.94577 | P11: =IFERROR(F11/B11,0)+'ENTRADAS PMO'!$D$30 -> 127.7286 | Q11: =IFERROR(K11/P11,0) -> 3725.0502 | R11: =MAX(0,IFERROR((K11-H11-I11)/P11,0)) -> 2730.7544 | S11: =IFERROR(R11/'ENTRADAS PMO'!$D$6,0) -> 0.91025148 | T11: =IFERROR((B11-R11)/B11,0) -> 0.04184055 | U11: ='ENTRADAS PMO'!$D$39 -> 180000 | V11: =IF(AND(M11>=Cenarios!$B$5,T11>=Cenarios!$B$6),"VERDE",IF(OR(M11<Cenarios!$B$7,T11<0),"VERMELHO","AMARELO")) -> AMARELO | W11: =IF(V11="VERDE","GO",IF(V11="VERMELHO","NO-GO","GO COM RESSALVAS")) -> GO COM RESSALVAS
A12: Agressivo | B12: ='ENTRADAS PMO'!$E$8 -> 3150 | C12: ='ENTRADAS PMO'!$E$9 -> 3330 | D12: ='ENTRADAS PMO'!$E$10 -> 0.95142857 | E12: ='ENTRADAS PMO'!$E$16 -> 111.03175 | F12: ='ENTRADAS PMO'!$E$18 -> 321770 | G12: ='ENTRADAS PMO'!$E$33 -> 110250 | H12: ='ENTRADAS PMO'!$E$24 -> 257400 | I12: ='ENTRADAS PMO'!$E$36 -> 0 | J12: =SUM(F12:I12) -> 689420 | K12: ='ENTRADAS PMO'!$E$107 -> 571042.67 | L12: =J12-K12 -> 118377.33 | M12: =IFERROR(L12/J12,0) -> 0.17170568 | N12: =IFERROR(J12/B12,0) -> 218.86349 | O12: =IFERROR(K12/B12,0) -> 181.28339 | P12: =IFERROR(F12/B12,0)+'ENTRADAS PMO'!$E$30 -> 137.14921 | Q12: =IFERROR(K12/P12,0) -> 4163.66 | R12: =MAX(0,IFERROR((K12-H12-I12)/P12,0)) -> 2286.8719 | S12: =IFERROR(R12/'ENTRADAS PMO'!$E$6,0) -> 0.65339198 | T12: =IFERROR((B12-R12)/B12,0) -> 0.27400891 | U12: ='ENTRADAS PMO'!$E$39 -> 200000 | V12: =IF(AND(M12>=Cenarios!$B$5,T12>=Cenarios!$B$6),"VERDE",IF(OR(M12<Cenarios!$B$7,T12<0),"VERMELHO","AMARELO")) -> VERDE | W12: =IF(V12="VERDE","GO",IF(V12="VERMELHO","NO-GO","GO COM RESSALVAS")) -> GO

Sheet ORÇAMENTO x REAL
A1: PIQUINZADA 2027 | ORÇAMENTO x REAL
A2: Rollup automático por categoria. Toda a informação vem da aba CUSTOS — nenhuma célula aqui é digitada manualmente.
A4: Categoria | B4: Orçamento inicial | C4: Orçamento revisado (aprovado) | D4: Valor contratado | E4: Valor realizado (pago) | F4: Saldo | G4: Desvio R$ | H4: Desvio % | I4: Projeção final (EAC) | J4: Classificação
A5: Atrações | B5: =SUMIF(CUSTOS!$A$5:$A$48,$A5,CUSTOS!$E$5:$E$48) -> 205000 | C5: =SUMIF(CUSTOS!$A$5:$A$48,$A5,CUSTOS!$F$5:$F$48) -> 205000 | D5: =SUMIF(CUSTOS!$A$5:$A$48,$A5,CUSTOS!$G$5:$G$48) -> 0 | E5: =SUMIF(CUSTOS!$A$5:$A$48,$A5,CUSTOS!$H$5:$H$48) -> 0 | F5: =C5-E5 -> 205000 | G5: =I5-C5 -> 0 | H5: =IFERROR(G5/C5,0) -> 0 | I5: =SUMIF(CUSTOS!$A$5:$A$48,$A5,CUSTOS!$O$5:$O$48) -> 205000 | J5: =IF(H5<=0,"Dentro do orçamento",IF(H5<=0.05,"Atenção","Estourado")) -> Dentro do orçamento
A6: Estrutura | B6: =SUMIF(CUSTOS!$A$5:$A$48,$A6,CUSTOS!$E$5:$E$48) -> 90000 | C6: =SUMIF(CUSTOS!$A$5:$A$48,$A6,CUSTOS!$F$5:$F$48) -> 90000 | D6: =SUMIF(CUSTOS!$A$5:$A$48,$A6,CUSTOS!$G$5:$G$48) -> 0 | E6: =SUMIF(CUSTOS!$A$5:$A$48,$A6,CUSTOS!$H$5:$H$48) -> 0 | F6: =C6-E6 -> 90000 | G6: =I6-C6 -> 0 | H6: =IFERROR(G6/C6,0) -> 0 | I6: =SUMIF(CUSTOS!$A$5:$A$48,$A6,CUSTOS!$O$5:$O$48) -> 90000 | J6: =IF(H6<=0,"Dentro do orçamento",IF(H6<=0.05,"Atenção","Estourado")) -> Dentro do orçamento
A7: Produção | B7: =SUMIF(CUSTOS!$A$5:$A$48,$A7,CUSTOS!$E$5:$E$48) -> 23000 | C7: =SUMIF(CUSTOS!$A$5:$A$48,$A7,CUSTOS!$F$5:$F$48) -> 23000 | D7: =SUMIF(CUSTOS!$A$5:$A$48,$A7,CUSTOS!$G$5:$G$48) -> 0 | E7: =SUMIF(CUSTOS!$A$5:$A$48,$A7,CUSTOS!$H$5:$H$48) -> 0 | F7: =C7-E7 -> 23000 | G7: =I7-C7 -> 0 | H7: =IFERROR(G7/C7,0) -> 0 | I7: =SUMIF(CUSTOS!$A$5:$A$48,$A7,CUSTOS!$O$5:$O$48) -> 23000 | J7: =IF(H7<=0,"Dentro do orçamento",IF(H7<=0.05,"Atenção","Estourado")) -> Dentro do orçamento
A8: Segurança | B8: =SUMIF(CUSTOS!$A$5:$A$48,$A8,CUSTOS!$E$5:$E$48) -> 22500 | C8: =SUMIF(CUSTOS!$A$5:$A$48,$A8,CUSTOS!$F$5:$F$48) -> 22500 | D8: =SUMIF(CUSTOS!$A$5:$A$48,$A8,CUSTOS!$G$5:$G$48) -> 0 | E8: =SUMIF(CUSTOS!$A$5:$A$48,$A8,CUSTOS!$H$5:$H$48) -> 0 | F8: =C8-E8 -> 22500 | G8: =I8-C8 -> 0 | H8: =IFERROR(G8/C8,0) -> 0 | I8: =SUMIF(CUSTOS!$A$5:$A$48,$A8,CUSTOS!$O$5:$O$48) -> 22500 | J8: =IF(H8<=0,"Dentro do orçamento",IF(H8<=0.05,"Atenção","Estourado")) -> Dentro do orçamento
A9: Marketing | B9: =SUMIF(CUSTOS!$A$5:$A$48,$A9,CUSTOS!$E$5:$E$48) -> 35000 | C9: =SUMIF(CUSTOS!$A$5:$A$48,$A9,CUSTOS!$F$5:$F$48) -> 35000 | D9: =SUMIF(CUSTOS!$A$5:$A$48,$A9,CUSTOS!$G$5:$G$48) -> 0 | E9: =SUMIF(CUSTOS!$A$5:$A$48,$A9,CUSTOS!$H$5:$H$48) -> 0 | F9: =C9-E9 -> 35000 | G9: =I9-C9 -> 0 | H9: =IFERROR(G9/C9,0) -> 0 | I9: =SUMIF(CUSTOS!$A$5:$A$48,$A9,CUSTOS!$O$5:$O$48) -> 35000 | J9: =IF(H9<=0,"Dentro do orçamento",IF(H9<=0.05,"Atenção","Estourado")) -> Dentro do orçamento
A10: Logística | B10: =SUMIF(CUSTOS!$A$5:$A$48,$A10,CUSTOS!$E$5:$E$48) -> 30000 | C10: =SUMIF(CUSTOS!$A$5:$A$48,$A10,CUSTOS!$F$5:$F$48) -> 30000 | D10: =SUMIF(CUSTOS!$A$5:$A$48,$A10,CUSTOS!$G$5:$G$48) -> 0 | E10: =SUMIF(CUSTOS!$A$5:$A$48,$A10,CUSTOS!$H$5:$H$48) -> 0 | F10: =C10-E10 -> 30000 | G10: =I10-C10 -> 0 | H10: =IFERROR(G10/C10,0) -> 0 | I10: =SUMIF(CUSTOS!$A$5:$A$48,$A10,CUSTOS!$O$5:$O$48) -> 30000 | J10: =IF(H10<=0,"Dentro do orçamento",IF(H10<=0.05,"Atenção","Estourado")) -> Dentro do orçamento
A11: Licenças | B11: =SUMIF(CUSTOS!$A$5:$A$48,$A11,CUSTOS!$E$5:$E$48) -> 4500 | C11: =SUMIF(CUSTOS!$A$5:$A$48,$A11,CUSTOS!$F$5:$F$48) -> 4500 | D11: =SUMIF(CUSTOS!$A$5:$A$48,$A11,CUSTOS!$G$5:$G$48) -> 0 | E11: =SUMIF(CUSTOS!$A$5:$A$48,$A11,CUSTOS!$H$5:$H$48) -> 0 | F11: =C11-E11 -> 4500 | G11: =I11-C11 -> 0 | H11: =IFERROR(G11/C11,0) -> 0 | I11: =SUMIF(CUSTOS!$A$5:$A$48,$A11,CUSTOS!$O$5:$O$48) -> 4500 | J11: =IF(H11<=0,"Dentro do orçamento",IF(H11<=0.05,"Atenção","Estourado")) -> Dentro do orçamento
A12: Administrativo | B12: =SUMIF(CUSTOS!$A$5:$A$48,$A12,CUSTOS!$E$5:$E$48) -> 30551.325 | C12: =SUMIF(CUSTOS!$A$5:$A$48,$A12,CUSTOS!$F$5:$F$48) -> 30551.325 | D12: =SUMIF(CUSTOS!$A$5:$A$48,$A12,CUSTOS!$G$5:$G$48) -> 0 | E12: =SUMIF(CUSTOS!$A$5:$A$48,$A12,CUSTOS!$H$5:$H$48) -> 0 | F12: =C12-E12 -> 30551.325 | G12: =I12-C12 -> 0 | H12: =IFERROR(G12/C12,0) -> 0 | I12: =SUMIF(CUSTOS!$A$5:$A$48,$A12,CUSTOS!$O$5:$O$48) -> 30551.325 | J12: =IF(H12<=0,"Dentro do orçamento",IF(H12<=0.05,"Atenção","Estourado")) -> Dentro do orçamento
A13: Contingência | B13: =SUMIF(CUSTOS!$A$5:$A$48,$A13,CUSTOS!$E$5:$E$48) -> 0 | C13: =SUMIF(CUSTOS!$A$5:$A$48,$A13,CUSTOS!$F$5:$F$48) -> 0 | D13: =SUMIF(CUSTOS!$A$5:$A$48,$A13,CUSTOS!$G$5:$G$48) -> 0 | E13: =SUMIF(CUSTOS!$A$5:$A$48,$A13,CUSTOS!$H$5:$H$48) -> 0 | F13: =C13-E13 -> 0 | G13: =I13-C13 -> 0 | H13: =IFERROR(G13/C13,0) -> 0 | I13: =SUMIF(CUSTOS!$A$5:$A$48,$A13,CUSTOS!$O$5:$O$48) -> 0 | J13: =IF(H13<=0,"Dentro do orçamento",IF(H13<=0.05,"Atenção","Estourado")) -> Dentro do orçamento
A14: TOTAL | B14: =SUM(B5:B13) -> 440551.33 | C14: =SUM(C5:C13) -> 440551.33 | D14: =SUM(D5:D13) -> 0 | E14: =SUM(E5:E13) -> 0 | F14: =SUM(F5:F13) -> 440551.33 | G14: =SUM(G5:G13) -> 0 | H14: =IFERROR(G14/C14,0) -> 0 | I14: =SUM(I5:I13) -> 440551.33

Sheet FLUXO DE CAIXA
A1: PIQUINZADA 2027 | FLUXO DE CAIXA
A2: Distribua o % de cada linha ao longo dos meses (deve somar 100%). Os totais anuais vêm do cenário selecionado abaixo.
A4: Cenário de referência | B4: Base
A5: Saldo inicial de caixa | B5: 0
A6: Coluna do cenário (auto) | B6: =IF('FLUXO DE CAIXA'!$B$4="Conservador","C",IF('FLUXO DE CAIXA'!$B$4="Base","D","E")) -> D
A8: Linha | B8: Jan | C8: Fev | D8: Mar | E8: Abr | F8: Mai | G8: Jun | H8: Jul | I8: Ago | J8: Set | K8: Out | L8: Nov | M8: Dez | N8: Total ano
A9: ENTRADAS
A10: Ingressos | B10: 0 | C10: 0.05 | D10: 0.1 | E10: 0.1 | F10: 0.1 | G10: 0.05 | H10: 0.05 | I10: 0.05 | J10: 0.1 | K10: 0.15 | L10: 0.15 | M10: 0.1 | N10: =SUM(B10:M10) -> 1
A11: Patrocínios | B11: 0.05 | C11: 0.1 | D11: 0.15 | E11: 0.15 | F11: 0.1 | G11: 0.05 | H11: 0.05 | I11: 0.05 | J11: 0.1 | K11: 0.1 | L11: 0.05 | M11: 0.05 | N11: =SUM(B11:M11) -> 1
A12: Bar / Ativações | B12: 0 | C12: 0 | D12: 0 | E12: 0 | F12: 0 | G12: 0 | H12: 0 | I12: 0 | J12: 0 | K12: 0 | L12: 0 | M12: 1 | N12: =SUM(B12:M12) -> 1
A13: Outras receitas | B13: 0 | C13: 0 | D13: 0 | E13: 0 | F13: 0 | G13: 0 | H13: 0 | I13: 0 | J13: 0 | K13: 0 | L13: 0.5 | M13: 0.5 | N13: =SUM(B13:M13) -> 1
A14: TOTAL ENTRADAS (R$) | B14: =SUM(B28:B31) -> 6350 | C14: =SUM(C28:C31) -> 26626.04 | D14: =SUM(D28:D31) -> 46902.08 | E14: =SUM(E28:E31) -> 46902.08 | F14: =SUM(F28:F31) -> 40552.08 | G14: =SUM(G28:G31) -> 20276.04 | H14: =SUM(H28:H31) -> 20276.04 | I14: =SUM(I28:I31) -> 20276.04 | ... M14: =SUM(M28:M31) -> 119707.78 | N14: =SUM(B14:M14) -> 491026.5
A16: SAÍDAS
A17: Atrações (cachês) | B17: 0 | C17: 0.2 | D17: 0 | E17: 0 | F17: 0 | G17: 0 | H17: 0 | I17: 0 | J17: 0 | K17: 0 | L17: 0.3 | M17: 0.5 | N17: =SUM(B17:M17) -> 1
A18: Estrutura | B18: 0 | C18: 0 | D18: 0 | E18: 0 | F18: 0 | G18: 0 | H18: 0 | I18: 0 | J18: 0.1 | K18: 0.2 | L18: 0.3 | M18: 0.4 | N18: =SUM(B18:M18) -> 1
A19: Operação (produção/segurança/licenças) | B19: 0 | C19: 0 | D19: 0 | E19: 0 | F19: 0 | G19: 0 | H19: 0 | I19: 0 | J19: 0.05 | K19: 0.15 | L19: 0.3 | M19: 0.5 | N19: =SUM(B19:M19) -> 1
A20: Marketing | B20: 0.05 | C20: 0.05 | D20: 0.05 | E20: 0.05 | F20: 0.1 | G20: 0.1 | H20: 0.1 | I20: 0.1 | J20: 0.1 | K20: 0.1 | L20: 0.1 | M20: 0.1 | N20: =SUM(B20:M20) -> 1
A21: Logística | B21: 0 | C21: 0 | D21: 0 | E21: 0 | F21: 0 | G21: 0 | H21: 0 | I21: 0 | J21: 0.1 | K21: 0.2 | L21: 0.3 | M21: 0.4 | N21: =SUM(B21:M21) -> 1
A22: Administrativo | B22: 0.08 | C22: 0.08 | D22: 0.08 | E22: 0.08 | F22: 0.09 | G22: 0.09 | H22: 0.09 | I22: 0.09 | J22: 0.09 | K22: 0.08 | L22: 0.08 | M22: 0.07 | N22: =SUM(B22:M22) -> 1
A23: Taxas / tributos / comissões | B23: 0 | C23: 0 | D23: 0 | E23: 0 | F23: 0 | G23: 0 | H23: 0 | I23: 0 | J23: 0 | K23: 0.2 | L23: 0.4 | M23: 0.4 | N23: =SUM(B23:M23) -> 1
A24: Contingência | B24: 0 | C24: 0 | D24: 0 | E24: 0 | F24: 0 | G24: 0 | H24: 0 | I24: 0 | J24: 0 | K24: 0.2 | L24: 0.3 | M24: 0.5 | N24: =SUM(B24:M24) -> 1
A25: TOTAL SAÍDAS (R$) | B25: =SUM(B32:B39) -> 2230 | C25: =SUM(C32:C39) -> 43230 | D25: =SUM(D32:D39) -> 2230 | E25: =SUM(E32:E39) -> 2230 | F25: =SUM(F32:F39) -> 4040 | G25: =SUM(G32:G39) -> 4040 | H25: =SUM(H32:H39) -> 4040 | I25: =SUM(I32:I39) -> 4040 | ... M25: =SUM(M32:M39) -> 206862.58 | N25: =SUM(B25:M25) -> 475795.43
A27: VALORES MENSAIS EM R$ (calculado)
A28: Ingressos | B28: =INDIRECT("'ENTRADAS PMO'!"&'FLUXO DE CAIXA'!$B$6&"18")*B10 -> 0 | C28: =INDIRECT("'ENTRADAS PMO'!"&'FLUXO DE CAIXA'!$B$6&"18")*C10 -> 13926.04 | D28: =INDIRECT("'ENTRADAS PMO'!"&'FLUXO DE CAIXA'!$B$6&"18")*D10 -> 27852.08 | E28: =INDIRECT("'ENTRADAS PMO'!"&'FLUXO DE CAIXA'!$B$6&"18")*E10 -> 27852.08 | F28: =INDIRECT("'ENTRADAS PMO'!"&'FLUXO DE CAIXA'!$B$6&"18")*F10 -> 27852.08 | G28: =INDIRECT("'ENTRADAS PMO'!"&'FLUXO DE CAIXA'!$B$6&"18")*G10 -> 13926.04 | H28: =INDIRECT("'ENTRADAS PMO'!"&'FLUXO DE CAIXA'!$B$6&"18")*H10 -> 13926.04 | I28: =INDIRECT("'ENTRADAS PMO'!"&'FLUXO DE CAIXA'!$B$6&"18")*I10 -> 13926.04 | ... M28: =INDIRECT("'ENTRADAS PMO'!"&'FLUXO DE CAIXA'!$B$6&"18")*M10 -> 27852.08 | N28: =SUM(B28:M28) -> 278520.8
A29: Patrocínios | B29: =INDIRECT("'ENTRADAS PMO'!"&'FLUXO DE CAIXA'!$B$6&"24")*B11 -> 6350 | C29: =INDIRECT("'ENTRADAS PMO'!"&'FLUXO DE CAIXA'!$B$6&"24")*C11 -> 12700 | D29: =INDIRECT("'ENTRADAS PMO'!"&'FLUXO DE CAIXA'!$B$6&"24")*D11 -> 19050 | E29: =INDIRECT("'ENTRADAS PMO'!"&'FLUXO DE CAIXA'!$B$6&"24")*E11 -> 19050 | F29: =INDIRECT("'ENTRADAS PMO'!"&'FLUXO DE CAIXA'!$B$6&"24")*F11 -> 12700 | G29: =INDIRECT("'ENTRADAS PMO'!"&'FLUXO DE CAIXA'!$B$6&"24")*G11 -> 6350 | H29: =INDIRECT("'ENTRADAS PMO'!"&'FLUXO DE CAIXA'!$B$6&"24")*H11 -> 6350 | I29: =INDIRECT("'ENTRADAS PMO'!"&'FLUXO DE CAIXA'!$B$6&"24")*I11 -> 6350 | ... M29: =INDIRECT("'ENTRADAS PMO'!"&'FLUXO DE CAIXA'!$B$6&"24")*M11 -> 6350 | N29: =SUM(B29:M29) -> 127000
A30: Bar / Ativações | B30: =INDIRECT("'ENTRADAS PMO'!"&'FLUXO DE CAIXA'!$B$6&"33")*B12 -> 0 | C30: =INDIRECT("'ENTRADAS PMO'!"&'FLUXO DE CAIXA'!$B$6&"33")*C12 -> 0 | D30: =INDIRECT("'ENTRADAS PMO'!"&'FLUXO DE CAIXA'!$B$6&"33")*D12 -> 0 | E30: =INDIRECT("'ENTRADAS PMO'!"&'FLUXO DE CAIXA'!$B$6&"33")*E12 -> 0 | F30: =INDIRECT("'ENTRADAS PMO'!"&'FLUXO DE CAIXA'!$B$6&"33")*F12 -> 0 | G30: =INDIRECT("'ENTRADAS PMO'!"&'FLUXO DE CAIXA'!$B$6&"33")*G12 -> 0 | H30: =INDIRECT("'ENTRADAS PMO'!"&'FLUXO DE CAIXA'!$B$6&"33")*H12 -> 0 | I30: =INDIRECT("'ENTRADAS PMO'!"&'FLUXO DE CAIXA'!$B$6&"33")*I12 -> 0 | ... M30: =INDIRECT("'ENTRADAS PMO'!"&'FLUXO DE CAIXA'!$B$6&"33")*M12 -> 85505.7 | N30: =SUM(B30:M30) -> 85505.7
A31: Outras receitas | B31: =INDIRECT("'ENTRADAS PMO'!"&'FLUXO DE CAIXA'!$B$6&"36")*B13 -> 0 | C31: =INDIRECT("'ENTRADAS PMO'!"&'FLUXO DE CAIXA'!$B$6&"36")*C13 -> 0 | D31: =INDIRECT("'ENTRADAS PMO'!"&'FLUXO DE CAIXA'!$B$6&"36")*D13 -> 0 | E31: =INDIRECT("'ENTRADAS PMO'!"&'FLUXO DE CAIXA'!$B$6&"36")*E13 -> 0 | F31: =INDIRECT("'ENTRADAS PMO'!"&'FLUXO DE CAIXA'!$B$6&"36")*F13 -> 0 | G31: =INDIRECT("'ENTRADAS PMO'!"&'FLUXO DE CAIXA'!$B$6&"36")*G13 -> 0 | H31: =INDIRECT("'ENTRADAS PMO'!"&'FLUXO DE CAIXA'!$B$6&"36")*H13 -> 0 | I31: =INDIRECT("'ENTRADAS PMO'!"&'FLUXO DE CAIXA'!$B$6&"36")*I13 -> 0 | ... M31: =INDIRECT("'ENTRADAS PMO'!"&'FLUXO DE CAIXA'!$B$6&"36")*M13 -> 0 | N31: =SUM(B31:M31) -> 0
A32: Atrações (cachês) | B32: =INDIRECT("'ENTRADAS PMO'!"&'FLUXO DE CAIXA'!$B$6&"44")*B17 -> 0 | C32: =INDIRECT("'ENTRADAS PMO'!"&'FLUXO DE CAIXA'!$B$6&"44")*C17 -> 41000 | D32: =INDIRECT("'ENTRADAS PMO'!"&'FLUXO DE CAIXA'!$B$6&"44")*D17 -> 0 | E32: =INDIRECT("'ENTRADAS PMO'!"&'FLUXO DE CAIXA'!$B$6&"44")*E17 -> 0 | F32: =INDIRECT("'ENTRADAS PMO'!"&'FLUXO DE CAIXA'!$B$6&"44")*F17 -> 0 | G32: =INDIRECT("'ENTRADAS PMO'!"&'FLUXO DE CAIXA'!$B$6&"44")*G17 -> 0 | H32: =INDIRECT("'ENTRADAS PMO'!"&'FLUXO DE CAIXA'!$B$6&"44")*H17 -> 0 | I32: =INDIRECT("'ENTRADAS PMO'!"&'FLUXO DE CAIXA'!$B$6&"44")*I17 -> 0 | ... M32: =INDIRECT("'ENTRADAS PMO'!"&'FLUXO DE CAIXA'!$B$6&"44")*M17 -> 102500 | N32: =SUM(B32:M32) -> 205000
A33: Estrutura | B33: =INDIRECT("'ENTRADAS PMO'!"&'FLUXO DE CAIXA'!$B$6&"58")*B18 -> 0 | C33: =INDIRECT("'ENTRADAS PMO'!"&'FLUXO DE CAIXA'!$B$6&"58")*C18 -> 0 | D33: =INDIRECT("'ENTRADAS PMO'!"&'FLUXO DE CAIXA'!$B$6&"58")*D18 -> 0 | E33: =INDIRECT("'ENTRADAS PMO'!"&'FLUXO DE CAIXA'!$B$6&"58")*E18 -> 0 | F33: =INDIRECT("'ENTRADAS PMO'!"&'FLUXO DE CAIXA'!$B$6&"58")*F18 -> 0 | G33: =INDIRECT("'ENTRADAS PMO'!"&'FLUXO DE CAIXA'!$B$6&"58")*G18 -> 0 | H33: =INDIRECT("'ENTRADAS PMO'!"&'FLUXO DE CAIXA'!$B$6&"58")*H18 -> 0 | I33: =INDIRECT("'ENTRADAS PMO'!"&'FLUXO DE CAIXA'!$B$6&"58")*I18 -> 0 | ... M33: =INDIRECT("'ENTRADAS PMO'!"&'FLUXO DE CAIXA'!$B$6&"58")*M18 -> 36000 | N33: =SUM(B33:M33) -> 90000
A34: Operação (produção/segurança/licenças) | B34: =INDIRECT("'ENTRADAS PMO'!"&'FLUXO DE CAIXA'!$B$6&"72")*B19 -> 0 | C34: =INDIRECT("'ENTRADAS PMO'!"&'FLUXO DE CAIXA'!$B$6&"72")*C19 -> 0 | D34: =INDIRECT("'ENTRADAS PMO'!"&'FLUXO DE CAIXA'!$B$6&"72")*D19 -> 0 | E34: =INDIRECT("'ENTRADAS PMO'!"&'FLUXO DE CAIXA'!$B$6&"72")*E19 -> 0 | F34: =INDIRECT("'ENTRADAS PMO'!"&'FLUXO DE CAIXA'!$B$6&"72")*F19 -> 0 | G34: =INDIRECT("'ENTRADAS PMO'!"&'FLUXO DE CAIXA'!$B$6&"72")*G19 -> 0 | H34: =INDIRECT("'ENTRADAS PMO'!"&'FLUXO DE CAIXA'!$B$6&"72")*H19 -> 0 | I34: =INDIRECT("'ENTRADAS PMO'!"&'FLUXO DE CAIXA'!$B$6&"72")*I19 -> 0 | ... M34: =INDIRECT("'ENTRADAS PMO'!"&'FLUXO DE CAIXA'!$B$6&"72")*M19 -> 25000 | N34: =SUM(B34:M34) -> 50000
A35: Marketing | B35: =INDIRECT("'ENTRADAS PMO'!"&'FLUXO DE CAIXA'!$B$6&"84")*B20 -> 1750 | C35: =INDIRECT("'ENTRADAS PMO'!"&'FLUXO DE CAIXA'!$B$6&"84")*C20 -> 1750 | D35: =INDIRECT("'ENTRADAS PMO'!"&'FLUXO DE CAIXA'!$B$6&"84")*D20 -> 1750 | E35: =INDIRECT("'ENTRADAS PMO'!"&'FLUXO DE CAIXA'!$B$6&"84")*E20 -> 1750 | F35: =INDIRECT("'ENTRADAS PMO'!"&'FLUXO DE CAIXA'!$B$6&"84")*F20 -> 3500 | G35: =INDIRECT("'ENTRADAS PMO'!"&'FLUXO DE CAIXA'!$B$6&"84")*G20 -> 3500 | H35: =INDIRECT("'ENTRADAS PMO'!"&'FLUXO DE CAIXA'!$B$6&"84")*H20 -> 3500 | I35: =INDIRECT("'ENTRADAS PMO'!"&'FLUXO DE CAIXA'!$B$6&"84")*I20 -> 3500 | ... M35: =INDIRECT("'ENTRADAS PMO'!"&'FLUXO DE CAIXA'!$B$6&"84")*M20 -> 3500 | N35: =SUM(B35:M35) -> 35000
A36: Logística | B36: =INDIRECT("'ENTRADAS PMO'!"&'FLUXO DE CAIXA'!$B$6&"93")*B21 -> 0 | C36: =INDIRECT("'ENTRADAS PMO'!"&'FLUXO DE CAIXA'!$B$6&"93")*C21 -> 0 | D36: =INDIRECT("'ENTRADAS PMO'!"&'FLUXO DE CAIXA'!$B$6&"93")*D21 -> 0 | E36: =INDIRECT("'ENTRADAS PMO'!"&'FLUXO DE CAIXA'!$B$6&"93")*E21 -> 0 | F36: =INDIRECT("'ENTRADAS PMO'!"&'FLUXO DE CAIXA'!$B$6&"93")*F21 -> 0 | G36: =INDIRECT("'ENTRADAS PMO'!"&'FLUXO DE CAIXA'!$B$6&"93")*G21 -> 0 | H36: =INDIRECT("'ENTRADAS PMO'!"&'FLUXO DE CAIXA'!$B$6&"93")*H21 -> 0 | I36: =INDIRECT("'ENTRADAS PMO'!"&'FLUXO DE CAIXA'!$B$6&"93")*I21 -> 0 | ... M36: =INDIRECT("'ENTRADAS PMO'!"&'FLUXO DE CAIXA'!$B$6&"93")*M21 -> 12000 | N36: =SUM(B36:M36) -> 30000
A37: Administrativo | B37: =INDIRECT("'ENTRADAS PMO'!"&'FLUXO DE CAIXA'!$B$6&"99")*B22 -> 480 | C37: =INDIRECT("'ENTRADAS PMO'!"&'FLUXO DE CAIXA'!$B$6&"99")*C22 -> 480 | D37: =INDIRECT("'ENTRADAS PMO'!"&'FLUXO DE CAIXA'!$B$6&"99")*D22 -> 480 | E37: =INDIRECT("'ENTRADAS PMO'!"&'FLUXO DE CAIXA'!$B$6&"99")*E22 -> 480 | F37: =INDIRECT("'ENTRADAS PMO'!"&'FLUXO DE CAIXA'!$B$6&"99")*F22 -> 540 | G37: =INDIRECT("'ENTRADAS PMO'!"&'FLUXO DE CAIXA'!$B$6&"99")*G22 -> 540 | H37: =INDIRECT("'ENTRADAS PMO'!"&'FLUXO DE CAIXA'!$B$6&"99")*H22 -> 540 | I37: =INDIRECT("'ENTRADAS PMO'!"&'FLUXO DE CAIXA'!$B$6&"99")*I22 -> 540 | ... M37: =INDIRECT("'ENTRADAS PMO'!"&'FLUXO DE CAIXA'!$B$6&"99")*M22 -> 420 | N37: =SUM(B37:M37) -> 6000
A38: Taxas / tributos / comissões | B38: =INDIRECT("'ENTRADAS PMO'!"&'FLUXO DE CAIXA'!$B$6&"104")*B23 -> 0 | C38: =INDIRECT("'ENTRADAS PMO'!"&'FLUXO DE CAIXA'!$B$6&"104")*C23 -> 0 | D38: =INDIRECT("'ENTRADAS PMO'!"&'FLUXO DE CAIXA'!$B$6&"104")*D23 -> 0 | E38: =INDIRECT("'ENTRADAS PMO'!"&'FLUXO DE CAIXA'!$B$6&"104")*E23 -> 0 | F38: =INDIRECT("'ENTRADAS PMO'!"&'FLUXO DE CAIXA'!$B$6&"104")*F23 -> 0 | G38: =INDIRECT("'ENTRADAS PMO'!"&'FLUXO DE CAIXA'!$B$6&"104")*G23 -> 0 | H38: =INDIRECT("'ENTRADAS PMO'!"&'FLUXO DE CAIXA'!$B$6&"104")*H23 -> 0 | I38: =INDIRECT("'ENTRADAS PMO'!"&'FLUXO DE CAIXA'!$B$6&"104")*I23 -> 0 | ... M38: =INDIRECT("'ENTRADAS PMO'!"&'FLUXO DE CAIXA'!$B$6&"104")*M23 -> 9820.53 | N38: =SUM(B38:M38) -> 24551.325
A39: Contingência | B39: =INDIRECT("'ENTRADAS PMO'!"&'FLUXO DE CAIXA'!$B$6&"106")*B24 -> 0 | C39: =INDIRECT("'ENTRADAS PMO'!"&'FLUXO DE CAIXA'!$B$6&"106")*C24 -> 0 | D39: =INDIRECT("'ENTRADAS PMO'!"&'FLUXO DE CAIXA'!$B$6&"106")*D24 -> 0 | E39: =INDIRECT("'ENTRADAS PMO'!"&'FLUXO DE CAIXA'!$B$6&"106")*E24 -> 0 | F39: =INDIRECT("'ENTRADAS PMO'!"&'FLUXO DE CAIXA'!$B$6&"106")*F24 -> 0 | G39: =INDIRECT("'ENTRADAS PMO'!"&'FLUXO DE CAIXA'!$B$6&"106")*G24 -> 0 | H39: =INDIRECT("'ENTRADAS PMO'!"&'FLUXO DE CAIXA'!$B$6&"106")*H24 -> 0 | I39: =INDIRECT("'ENTRADAS PMO'!"&'FLUXO DE CAIXA'!$B$6&"106")*I24 -> 0 | ... M39: =INDIRECT("'ENTRADAS PMO'!"&'FLUXO DE CAIXA'!$B$6&"106")*M24 -> 17622.053 | N39: =SUM(B39:M39) -> 35244.106
A41: SALDO DE CAIXA
A42: Saldo do período | B42: =B14-B25 -> 4120 | C42: =C14-C25 -> -16603.96 | D42: =D14-D25 -> 44672.08 | E42: =E14-E25 -> 44672.08 | F42: =F14-F25 -> 36512.08 | G42: =G14-G25 -> 16236.04 | H42: =H14-H25 -> 16236.04 | I42: =I14-I25 -> 16236.04 | ... M42: =M14-M25 -> -87154.803 | N42: =SUM(B42:M42) -> 15231.069
A43: Saldo acumulado | B43: ='FLUXO DE CAIXA'!$B$5+B42 -> 4120 | C43: =B43+C42 -> -12483.96 | D43: =C43+D42 -> 32188.12 | E43: =D43+E42 -> 76860.2 | F43: =E43+F42 -> 113372.28 | G43: =F43+G42 -> 129608.32 | H43: =G43+H42 -> 145844.36 | I43: =H43+I42 -> 162080.4 | J43: =I43+J42 -> 184092.48 | ... M43: =L43+M42 -> 15231.069
A45: Necessidade máxima de capital de giro | B45: =MAX(0,-MIN(B43:M43)) -> 12483.96
A46: Resultado final do exercício (lucro/prejuízo) | B46: =N14-N25 -> 15231.069
...

Sheet BREAK-EVEN
A1: PIQUINZADA 2027 | PONTO DE EQUILÍBRIO
A2: Todas as métricas derivam do motor de cálculo (aba Cenarios) e de ENTRADAS PMO.
A4: Indicador | B4: CONSERVADOR | C4: BASE | D4: AGRESSIVO
A5: Ponto de equilíbrio — ingressos SEM patrocínio | B5: =Cenarios!$Q$10 -> 4204.1798 | C5: =Cenarios!$Q$11 -> 3725.0502 | D5: =Cenarios!$Q$12 -> 4163.66
A6: Ponto de equilíbrio — ingressos COM patrocínio esperado | B6: =Cenarios!$R$10 -> 3705.3733 | C6: =Cenarios!$R$11 -> 2730.7544 | D6: =Cenarios!$R$12 -> 2286.8719
A7: Quantidade mínima de ingressos a vender | B7: =Cenarios!$R$10 -> 3705.3733 | C7: =Cenarios!$R$11 -> 2730.7544 | D7: =Cenarios!$R$12 -> 2286.8719
A8: % mínimo de ocupação da capacidade | B8: =Cenarios!$S$10 -> 1.6842606 | C8: =Cenarios!$S$11 -> 0.91025148 | D8: =Cenarios!$S$12 -> 0.65339198
A9: Receita mínima necessária (= Custo Total) | B9: =Cenarios!$K$10 -> 403049.8 | C9: =Cenarios!$K$11 -> 475795.43 | D9: =Cenarios!$K$12 -> 571042.67
A10: Patrocínio mínimo necessário (cobrir o cachê) | B10: =Cenarios!$U$10 -> 160000 | C10: =Cenarios!$U$11 -> 180000 | D10: =Cenarios!$U$12 -> 200000
A11: Margem de segurança (sobre pagantes planejados) | B11: =Cenarios!$T$10 -> -1.4060865 | C11: =Cenarios!$T$11 -> 0.04184055 | D11: =Cenarios!$T$12 -> 0.27400891
A12: Ticket médio mínimo (mantendo demais premissas) | B12: =(Cenarios!$K$10-'ENTRADAS PMO'!$C$24-'ENTRADAS PMO'!$C$33-'ENTRADAS PMO'!$C$36)/Cenarios!$B$10/(1-'ENTRADAS PMO'!$C$13-'ENTRADAS PMO'!$C$14-'ENTRADAS PMO'!$C$15) -> 226.81381 | C12: =(Cenarios!$K$11-'ENTRADAS PMO'!$D$24-'ENTRADAS PMO'!$D$33-'ENTRADAS PMO'!$D$36)/Cenarios!$B$11/(1-'ENTRADAS PMO'!$D$13-'ENTRADAS PMO'!$D$14-'ENTRADAS PMO'!$D$15) -> 100.41561 | D12: =(Cenarios!$K$12-'ENTRADAS PMO'!$E$24-'ENTRADAS PMO'!$E$33-'ENTRADAS PMO'!$E$36)/Cenarios!$B$12/(1-'ENTRADAS PMO'!$E$13-'ENTRADAS PMO'!$E$14-'ENTRADAS PMO'!$E$15) -> 70.183806
A14: SIMULADORES "E SE...?"
A15: Cenário de referência para os simuladores | B15: Base
B16: =IF('BREAK-EVEN'!$B$15="Conservador","C",IF('BREAK-EVEN'!$B$15="Base","D","E")) -> D
A18: 1) Se o patrocínio for R$ ___, quantos ingressos preciso vender?
A19: Patrocínio hipotético (R$) | B19: 100000
A20: → Ingressos necessários | B20: =MAX(0,(INDIRECT("'ENTRADAS PMO'!"&'BREAK-EVEN'!$B$16&"107")-'BREAK-EVEN'!$B$19-INDIRECT("'ENTRADAS PMO'!"&'BREAK-EVEN'!$B$16&"36"))/(INDIRECT("'ENTRADAS PMO'!"&'BREAK-EVEN'!$B$16&"16")*(1-INDIRECT("'ENTRADAS PMO'!"&'BREAK-EVEN'!$B$16&"13")-INDIRECT("'ENTRADAS PMO'!"&'BREAK-EVEN'!$B$16&"14")-INDIRECT("'ENTRADAS PMO'!"&'BREAK-EVEN'!$B$16&"15"))+INDIRECT("'ENTRADAS PMO'!"&'BREAK-EVEN'!$B$16&"30"))) -> 2942.1401
A22: 2) Se eu vender ___ ingressos, quanto de patrocínio preciso?
A23: Ingressos hipotéticos | B23: 2500
A24: → Patrocínio necessário | B24: =MAX(0,INDIRECT("'ENTRADAS PMO'!"&'BREAK-EVEN'!$B$16&"107")-'BREAK-EVEN'!$B$23*(INDIRECT("'ENTRADAS PMO'!"&'BREAK-EVEN'!$B$16&"16")*(1-INDIRECT("'ENTRADAS PMO'!"&'BREAK-EVEN'!$B$16&"13")-INDIRECT("'ENTRADAS PMO'!"&'BREAK-EVEN'!$B$16&"14")-INDIRECT("'ENTRADAS PMO'!"&'BREAK-EVEN'!$B$16&"15"))+INDIRECT("'ENTRADAS PMO'!"&'BREAK-EVEN'!$B$16&"30"))-INDIRECT("'ENTRADAS PMO'!"&'BREAK-EVEN'!$B$16&"36")) -> 156473.94
A26: 3) Se o cachê da atração principal subir para R$ ___, qual o novo break-even?
A27: Novo cachê hipotético (R$) | B27: 220000
A28: → Novo custo total do cenário | B28: =(((INDIRECT("'ENTRADAS PMO'!"&'BREAK-EVEN'!$B$16&"103")-INDIRECT("'ENTRADAS PMO'!"&'BREAK-EVEN'!$B$16&"39")+'BREAK-EVEN'!$B$27)+INDIRECT("'ENTRADAS PMO'!"&'BREAK-EVEN'!$B$16&"104"))*(1+INDIRECT("'ENTRADAS PMO'!"&'BREAK-EVEN'!$B$16&"100"))) -> 518995.43
A29: → Novo break-even (ingressos, com patrocínio esperado) | B29: =MAX(0,((((INDIRECT("'ENTRADAS PMO'!"&'BREAK-EVEN'!$B$16&"103")-INDIRECT("'ENTRADAS PMO'!"&'BREAK-EVEN'!$B$16&"39")+'BREAK-EVEN'!$B$27)+INDIRECT("'ENTRADAS PMO'!"&'BREAK-EVEN'!$B$16&"104"))*(1+INDIRECT("'ENTRADAS PMO'!"&'BREAK-EVEN'!$B$16&"100")))-INDIRECT("'ENTRADAS PMO'!"&'BREAK-EVEN'!$B$16&"24")-INDIRECT("'ENTRADAS PMO'!"&'BREAK-EVEN'!$B$16&"36"))/(INDIRECT("'ENTRADAS PMO'!"&'BREAK-EVEN'!$B$16&"16")*(1-INDIRECT("'ENTRADAS PMO'!"&'BREAK-EVEN'!$B$16&"13")-INDIRECT("'ENTRADAS PMO'!"&'BREAK-EVEN'!$B$16&"14")-INDIRECT("'ENTRADAS PMO'!"&'BREAK-EVEN'!$B$16&"15"))+INDIRECT("'ENTRADAS PMO'!"&'BREAK-EVEN'!$B$16&"30"))) -> 3068.9716
A31: 4) Qual o preço médio mínimo do ingresso para atingir a margem alvo ___?
A32: Margem líquida alvo (%) | B32: 0.1
A33: → Ticket médio mínimo necessário | B33: =IFERROR((INDIRECT("'ENTRADAS PMO'!"&'BREAK-EVEN'!$B$16&"107")/(1-'BREAK-EVEN'!$B$32)-INDIRECT("'ENTRADAS PMO'!"&'BREAK-EVEN'!$B$16&"24")-INDIRECT("'ENTRADAS PMO'!"&'BREAK-EVEN'!$B$16&"33")-INDIRECT("'ENTRADAS PMO'!"&'BREAK-EVEN'!$B$16&"36"))/INDIRECT("'ENTRADAS PMO'!"&'BREAK-EVEN'!$B$16&"8")/(1-INDIRECT("'ENTRADAS PMO'!"&'BREAK-EVEN'!$B$16&"13")-INDIRECT("'ENTRADAS PMO'!"&'BREAK-EVEN'!$B$16&"14")-INDIRECT("'ENTRADAS PMO'!"&'BREAK-EVEN'!$B$16&"15")),0) -> 120.57814

Sheet SENSIBILIDADE
A1: PIQUINZADA 2027 | ANÁLISE DE SENSIBILIDADE
A2: Impacto no RESULTADO do cenário selecionado quando cada variável muda isoladamente (demais premissas mantidas fixas).
A4: Cenário de referência | B4: Base
A5: Coluna do cenário (auto) | B5: =IF(SENSIBILIDADE!$B$4="Conservador","C",IF(SENSIBILIDADE!$B$4="Base","D","E")) -> D
A7: Resultado do cenário (referência) | B7: =INDIRECT("'ENTRADAS PMO'!"&SENSIBILIDADE!$B$5&"18")+INDIRECT("'ENTRADAS PMO'!"&SENSIBILIDADE!$B$5&"33")+INDIRECT("'ENTRADAS PMO'!"&SENSIBILIDADE!$B$5&"24")+INDIRECT("'ENTRADAS PMO'!"&SENSIBILIDADE!$B$5&"36")-INDIRECT("'ENTRADAS PMO'!"&SENSIBILIDADE!$B$5&"107") -> 15231.069
A8: Receita total (referência, base de % de impacto) | B8: =INDIRECT("'ENTRADAS PMO'!"&SENSIBILIDADE!$B$5&"18")+INDIRECT("'ENTRADAS PMO'!"&SENSIBILIDADE!$B$5&"33")+INDIRECT("'ENTRADAS PMO'!"&SENSIBILIDADE!$B$5&"24")+INDIRECT("'ENTRADAS PMO'!"&SENSIBILIDADE!$B$5&"36") -> 491026.5
A10: Variável | B10: -30% | C10: -20% | D10: -10% | E10: BASE | F10: +10% | G10: +20%
A11: Venda de ingressos (qtd. de pagantes) | B11: =(INDIRECT("'ENTRADAS PMO'!"&SENSIBILIDADE!$B$5&"18")*(1+-0.3)+INDIRECT("'ENTRADAS PMO'!"&SENSIBILIDADE!$B$5&"33")*(1+-0.3)+INDIRECT("'ENTRADAS PMO'!"&SENSIBILIDADE!$B$5&"24")+INDIRECT("'ENTRADAS PMO'!"&SENSIBILIDADE!$B$5&"36"))-INDIRECT("'ENTRADAS PMO'!"&SENSIBILIDADE!$B$5&"107") -> -93976.881 | C11: =(INDIRECT("'ENTRADAS PMO'!"&SENSIBILIDADE!$B$5&"18")*(1+-0.2)+INDIRECT("'ENTRADAS PMO'!"&SENSIBILIDADE!$B$5&"33")*(1+-0.2)+INDIRECT("'ENTRADAS PMO'!"&SENSIBILIDADE!$B$5&"24")+INDIRECT("'ENTRADAS PMO'!"&SENSIBILIDADE!$B$5&"36"))-INDIRECT("'ENTRADAS PMO'!"&SENSIBILIDADE!$B$5&"107") -> -57574.231 | D11: =(INDIRECT("'ENTRADAS PMO'!"&SENSIBILIDADE!$B$5&"18")*(1+-0.1)+INDIRECT("'ENTRADAS PMO'!"&SENSIBILIDADE!$B$5&"33")*(1+-0.1)+INDIRECT("'ENTRADAS PMO'!"&SENSIBILIDADE!$B$5&"24")+INDIRECT("'ENTRADAS PMO'!"&SENSIBILIDADE!$B$5&"36"))-INDIRECT("'ENTRADAS PMO'!"&SENSIBILIDADE!$B$5&"107") -> -21171.581 | E11: =(INDIRECT("'ENTRADAS PMO'!"&SENSIBILIDADE!$B$5&"18")*(1+0)+INDIRECT("'ENTRADAS PMO'!"&SENSIBILIDADE!$B$5&"33")*(1+0)+INDIRECT("'ENTRADAS PMO'!"&SENSIBILIDADE!$B$5&"24")+INDIRECT("'ENTRADAS PMO'!"&SENSIBILIDADE!$B$5&"36"))-INDIRECT("'ENTRADAS PMO'!"&SENSIBILIDADE!$B$5&"107") -> 15231.069 | F11: =(INDIRECT("'ENTRADAS PMO'!"&SENSIBILIDADE!$B$5&"18")*(1+0.1)+INDIRECT("'ENTRADAS PMO'!"&SENSIBILIDADE!$B$5&"33")*(1+0.1)+INDIRECT("'ENTRADAS PMO'!"&SENSIBILIDADE!$B$5&"24")+INDIRECT("'ENTRADAS PMO'!"&SENSIBILIDADE!$B$5&"36"))-INDIRECT("'ENTRADAS PMO'!"&SENSIBILIDADE!$B$5&"107") -> 51633.719 | G11: =(INDIRECT("'ENTRADAS PMO'!"&SENSIBILIDADE!$B$5&"18")*(1+0.2)+INDIRECT("'ENTRADAS PMO'!"&SENSIBILIDADE!$B$5&"33")*(1+0.2)+INDIRECT("'ENTRADAS PMO'!"&SENSIBILIDADE!$B$5&"24")+INDIRECT("'ENTRADAS PMO'!"&SENSIBILIDADE!$B$5&"36"))-INDIRECT("'ENTRADAS PMO'!"&SENSIBILIDADE!$B$5&"107") -> 88036.369
